#VRML_SIM R2023b utf8

EXTERNPROTO "https://raw.githubusercontent.com/cyberbotics/webots/R2023b/projects/objects/backgrounds/protos/TexturedBackground.proto"
EXTERNPROTO "https://raw.githubusercontent.com/cyberbotics/webots/R2023b/projects/objects/backgrounds/protos/TexturedBackgroundLight.proto"
EXTERNPROTO "https://raw.githubusercontent.com/cyberbotics/webots/R2023b/projects/objects/floors/protos/RectangleArena.proto"
EXTERNPROTO "https://raw.githubusercontent.com/cyberbotics/webots/R2023b/projects/robots/dji/mavic/protos/Mavic2Pro.proto"

WorldInfo {
  defaultDamping Damping {
  }
  contactProperties [
    ContactProperties {
      material1 "solid"
      coulombFriction [
        0
      ]
    }
  ]
}
Viewpoint {
  orientation 0.08472802295685426 -0.11499926055612922 -0.9897455896326924 5.003332406272049
  position -0.2420105065476526 -0.9139638413348057 0.25962996697212154
}
TexturedBackground {
}
TexturedBackgroundLight {
}
RectangleArena {
  floorSize 5 5
}
Solid {
  translation 1.06 0.32 0
  children [
    Shape {
      geometry Box {
        size 0.1 0.05 0.05
      }
    }
  ]
  boundingObject Box {
    size 0.1 0.05 0.05
  }
  physics Physics {
  }
}
Mavic2Pro {
  translation 0 0 0.215
  bodySlot [
    HingeJoint {
      jointParameters HingeJointParameters {
        anchor -0.0725 0 -0.107
      }
      device [
        PositionSensor {
          name "PS2"
        }
        RotationalMotor {
          name "RM2"
        }
      ]
      endPoint Solid {
        translation -0.0725 0 -0.107
        rotation 1 0 0 0
        children [
          Solid {
            translation -0.005 0 -0.0175
            children [
              DEF arm Shape {
                appearance PBRAppearance {
                  baseColor 0 1 0
                  roughness 1
                  metalness 0
                }
                geometry Box {
                  size 0.005 0.005 0.04
                }
              }
            ]
            boundingObject USE arm
            physics Physics {
            }
          }
          DEF axle Shape {
            appearance PBRAppearance {
              baseColor 1 0 1
              roughness 1
              metalness 0
            }
            geometry Box {
              size 0.005 0.005 0.005
            }
          }
        ]
        name "solid(2)"
        boundingObject USE axle
        physics Physics {
        }
      }
    }
    HingeJoint {
      jointParameters HingeJointParameters {
        axis 1 0 1
        anchor -0.05 -0.01 -0.107
      }
      device [
        PositionSensor {
          name "PS1"
        }
        RotationalMotor {
          name "RM1"
          acceleration 1
        }
      ]
      endPoint Solid {
        translation -0.05 -0.01 -0.107
        rotation 3.326119999976719e-06 -1.7135199999880057e-06 0.9999999999930004 0.7853979999999999
        children [
          Solid {
            translation 0 -0.005 -0.0175
            rotation -1 2.0827e-07 4.77898e-07 3.14159
            children [
              DEF arm Shape {
                appearance PBRAppearance {
                  baseColor 0 1 0
                  roughness 1
                  metalness 0
                }
                geometry Box {
                  size 0.005 0.005 0.04
                }
              }
            ]
            boundingObject USE arm
            physics Physics {
            }
          }
          DEF axle Shape {
            appearance PBRAppearance {
              baseColor 1 0 1
              roughness 1
              metalness 0
            }
            geometry Box {
              size 0.005 0.005 0.005
            }
          }
        ]
        name "solid(1)"
        contactMaterial "solid"
        boundingObject USE axle
        physics Physics {
          density 1
        }
      }
    }
    Pose {
      translation -0.06 0 -0.107
      rotation 0 1 0 -5.307179586466759e-06
      children [
        DEF body Shape {
          appearance PBRAppearance {
            baseColor 0 1 1
            roughness 1
            metalness 0
          }
          geometry Box {
            size 0.02 0.02 0.005
          }
        }
      ]
    }
    HingeJoint {
      jointParameters HingeJointParameters {
        axis 1 0 1
        anchor -0.05 0.01 -0.107
      }
      device [
        PositionSensor {
          name "PS"
        }
        RotationalMotor {
          name "RM"
          acceleration 1
        }
      ]
      endPoint Solid {
        translation -0.05 0.01 -0.107
        rotation 3.5635499994667474e-06 1.140279999999481e-06 -0.9999999999930004 0.785395307179585
        children [
          Solid {
            translation 0 0.005 -0.0175
            rotation 1 0 0 -1.5707953071795862
            children [
              DEF arm Shape {
                appearance PBRAppearance {
                  baseColor 0 1 0
                  roughness 1
                  metalness 0
                }
                geometry Box {
                  size 0.005 0.04 0.005
                }
              }
            ]
            boundingObject USE arm
            physics Physics {
            }
          }
          DEF axle Shape {
            appearance PBRAppearance {
              baseColor 1 0 1
              roughness 1
              metalness 0
            }
            geometry Box {
              size 0.005 0.005 0.005
            }
          }
        ]
        contactMaterial "solid"
        boundingObject USE axle
        physics Physics {
        }
      }
    }
    Pose {
      translation -0.06 0 -0.08
      children [
        DEF body Shape {
          appearance PBRAppearance {
            baseColor 0 1 1
            roughness 1
            metalness 0
          }
          geometry Box {
            size 0.005 0.005 0.05
          }
        }
      ]
    }
  ]
}
