#VRML_SIM R2023b utf8

EXTERNPROTO "https://raw.githubusercontent.com/cyberbotics/webots/R2023b/projects/objects/backgrounds/protos/TexturedBackground.proto"
EXTERNPROTO "https://raw.githubusercontent.com/cyberbotics/webots/R2023b/projects/objects/backgrounds/protos/TexturedBackgroundLight.proto"
EXTERNPROTO "https://raw.githubusercontent.com/cyberbotics/webots/R2023b/projects/objects/floors/protos/RectangleArena.proto"
EXTERNPROTO "https://raw.githubusercontent.com/cyberbotics/webots/R2023b/projects/robots/dji/mavic/protos/Mavic2Pro.proto"
EXTERNPROTO "https://raw.githubusercontent.com/cyberbotics/webots/R2023b/projects/objects/geometries/protos/TexturedParallelepiped.proto"

WorldInfo {
  defaultDamping Damping {
  }
  contactProperties [
    ContactProperties {
      material1 "solid"
      coulombFriction [
        0
      ]
    }
  ]
}
Viewpoint {
  orientation -0.08553981175214231 -0.2667063292745956 0.9599743093074309 5.6383391218038925
  position -0.4562662406896527 0.3123727424205436 0.1343161196200979
}
TexturedBackground {
}
TexturedBackgroundLight {
}
RectangleArena {
  floorSize 5 5
}
Solid {
  translation -0.43 -0.02 0.01
  children [
    DEF box Shape {
      appearance PBRAppearance {
      }
      geometry Box {
        size 0.04 0.03 0.02
      }
    }
  ]
  boundingObject USE box
  physics Physics {
  }
}
Mavic2Pro {
  translation -0.01 1.85752e-07 0.155
  rotation 1 0 0 -5.307179586466759e-06
  bodySlot [
    HingeJoint {
      jointParameters HingeJointParameters {
        axis 0 -1 0
        anchor -0.0725 0 -0.107
      }
      device [
        PositionSensor {
          name "PS2"
        }
        RotationalMotor {
          name "RM2"
          acceleration 1
        }
      ]
      endPoint Solid {
        translation -0.0725 0 -0.107
        rotation 2.858809999979949e-06 2.419629999983029e-06 -0.9999999999929862 1.5707953071795862
        children [
          Solid {
            translation 0 -0.027 -0.0193
            rotation -1.14927e-06 1.40791e-07 -1 -3.1415853071795863
            children [
              DEF claw Shape {
                appearance PBRAppearance {
                  baseColor 0 1 0
                  roughness 1
                  metalness 0
                }
                geometry TexturedParallelepiped {
                  size 0.005 0.01 0.04
                  angles 0 1 0
                }
              }
            ]
            name "solid(1)"
            boundingObject USE claw
            physics Physics {
            }
          }
          Solid {
            translation 0 -0.0225 0
            rotation -1 6.86169e-07 2.69628e-07 1.57079
            children [
              DEF arm Shape {
                appearance PBRAppearance {
                  baseColor 0 1 0
                  roughness 1
                  metalness 0
                }
                geometry Box {
                  size 0.005 0.005 0.04
                }
              }
            ]
            boundingObject USE arm
            physics Physics {
            }
          }
          DEF axle Shape {
            appearance PBRAppearance {
              baseColor 1 0 1
              roughness 1
              metalness 0
            }
            geometry Box {
              size 0.005 0.005 0.005
            }
          }
        ]
        name "solid(2)"
        contactMaterial "solid"
        boundingObject USE axle
        physics Physics {
        }
      }
    }
    HingeJoint {
      jointParameters HingeJointParameters {
        axis -1 0 0
        anchor -0.06 0.0125 -0.107
      }
      device [
        PositionSensor {
          name "PS3"
        }
        RotationalMotor {
          name "RM3"
          acceleration 1
        }
      ]
      endPoint Solid {
        translation -0.06 0.0125 -0.107
        rotation -2.1958999999922994e-07 -2.639219999990745e-06 0.9999999999964932 3.14159
        children [
          Solid {
            translation 0 -0.027 -0.0193
            rotation -1.14927e-06 1.40791e-07 -1 -3.1415853071795863
            children [
              DEF claw Shape {
                appearance PBRAppearance {
                  baseColor 0 1 0
                  roughness 1
                  metalness 0
                }
                geometry TexturedParallelepiped {
                  size 0.005 0.01 0.04
                  angles 0 1 0
                }
              }
            ]
            name "solid(1)"
            boundingObject USE claw
            physics Physics {
            }
          }
          Solid {
            translation 0 -0.0225 0
            rotation -1 6.86169e-07 2.69628e-07 1.57079
            children [
              DEF arm Shape {
                appearance PBRAppearance {
                  baseColor 0 1 0
                  roughness 1
                  metalness 0
                }
                geometry Box {
                  size 0.005 0.005 0.04
                }
              }
            ]
            boundingObject USE arm
            physics Physics {
            }
          }
          DEF axle Shape {
            appearance PBRAppearance {
              baseColor 1 0 1
              roughness 1
              metalness 0
            }
            geometry Box {
              size 0.005 0.005 0.005
            }
          }
        ]
        name "solid(3)"
        contactMaterial "solid"
        boundingObject USE axle
        physics Physics {
          density 1
        }
      }
    }
    HingeJoint {
      jointParameters HingeJointParameters {
        anchor -0.06 -0.0125 -0.107
      }
      device [
        PositionSensor {
          name "PS1"
        }
        RotationalMotor {
          name "RM1"
          acceleration 1
        }
      ]
      endPoint Solid {
        translation -0.06 -0.0125 -0.107
        rotation 0.9945896626077083 -0.08275237192810922 -0.06279687869756383 5.307156870259904e-06
        children [
          Solid {
            translation 0 -0.027 -0.0193
            rotation -1.14927e-06 1.40791e-07 -1 -3.1415853071795863
            children [
              DEF claw Shape {
                appearance PBRAppearance {
                  baseColor 0 1 0
                  roughness 1
                  metalness 0
                }
                geometry TexturedParallelepiped {
                  size 0.005 0.01 0.04
                  angles 0 1 0
                }
              }
            ]
            name "solid(1)"
            boundingObject USE claw
            physics Physics {
            }
          }
          Solid {
            translation 0 -0.0225 0
            rotation -1 6.86169e-07 2.69628e-07 1.57079
            children [
              DEF arm Shape {
                appearance PBRAppearance {
                  baseColor 0 1 0
                  roughness 1
                  metalness 0
                }
                geometry Box {
                  size 0.005 0.005 0.04
                }
              }
            ]
            boundingObject USE arm
            physics Physics {
            }
          }
          DEF axle Shape {
            appearance PBRAppearance {
              baseColor 1 0 1
              roughness 1
              metalness 0
            }
            geometry Box {
              size 0.005 0.005 0.005
            }
          }
        ]
        name "solid(1)"
        contactMaterial "solid"
        boundingObject USE axle
        physics Physics {
        }
      }
    }
    Pose {
      translation -0.06 0 -0.107
      rotation 0 1 0 -5.307179586466759e-06
      children [
        DEF body Shape {
          appearance PBRAppearance {
            baseColor 0 1 1
            roughness 1
            metalness 0
          }
          geometry Box {
            size 0.02 0.02 0.005
          }
        }
      ]
    }
    HingeJoint {
      jointParameters HingeJointParameters {
        axis 0 1 0
        anchor -0.0475 0 -0.107
      }
      device [
        PositionSensor {
          name "PS"
        }
        RotationalMotor {
          name "RM"
          acceleration 1
        }
      ]
      endPoint Solid {
        translation -0.0475 0 -0.107
        rotation 1.5456099999968308e-06 1.3081699999973181e-06 -0.9999999999979499 1.570795307181636
        children [
          Solid {
            translation 0 0.027 -0.0193
            rotation 0.04429487720597257 0.3615768139335216 -0.9312895207608595 6.35691e-06
            children [
              DEF claw Shape {
                appearance PBRAppearance {
                  baseColor 0 1 0
                  roughness 1
                  metalness 0
                }
                geometry TexturedParallelepiped {
                  size 0.005 0.01 0.04
                  angles 0 1 0
                }
              }
            ]
            name "solid(1)"
            boundingObject USE claw
            physics Physics {
            }
          }
          Solid {
            translation 0 0.0225 0
            rotation 1 0 0 1.01503e-06
            children [
              DEF arm Shape {
                appearance PBRAppearance {
                  baseColor 0 1 0
                  roughness 1
                  metalness 0
                }
                geometry Box {
                  size 0.005 0.04 0.005
                }
              }
            ]
            boundingObject USE arm
            physics Physics {
            }
          }
          DEF axle Shape {
            appearance PBRAppearance {
              baseColor 1 0 1
              roughness 1
              metalness 0
            }
            geometry Box {
              size 0.005 0.005 0.005
            }
          }
        ]
        contactMaterial "solid"
        boundingObject USE axle
        physics Physics {
        }
      }
    }
    Pose {
      translation -0.06 0 -0.08
      children [
        DEF body Shape {
          appearance PBRAppearance {
            baseColor 0 1 1
            roughness 1
            metalness 0
          }
          geometry Box {
            size 0.005 0.005 0.05
          }
        }
      ]
    }
  ]
}
